Workbook

Sheet Mountlly-R
A1: فرم رو ميزي بررسي اطلاعات مصرف انرژي ( جلسات ماهيانه پايلوت اداره نت )
A2: گزارش عملکرد ماهیانه کمیته انرژی | I2: مدیریت رنگ | T2: سالن هاي | V2: رنگ1و رنگ3
A3: سالن: | C3: رنگ 1 | G3: ارديبهشت | M3: / | N3: خرداد | T3: 1405
A4: گزارش مصرف ماهانه حامل های انرژي
A5: ردیف | B5: نوع حامل | D5: ارديبهشت ماه | L5: کاهش یا افزایش مصرف نسبت به مشابه ماه سال قبل | U5: کاهش یا افزایش مصرف ماه جاري نسبت به ماه قبل
D6: 1405 | H6: 1404 | L6: درصد | N6: دلايل تغييرات | U6: درصد | W6: دلايل تغييرات
D7: مقدار مصرف (KWH-m^3) | F7: سرانه مصرف به ازای بدنه | G7: مبلغ قبض (به ریال) | H7: مقدار مصرف (KWH-m^3) | J7: سرانه مصرف به ازای بدنه | L7: افزايش يا كاهش مصرف % | N7: درصد افزايش/كاهش | P7: رخ داد ها | U7: افزايش يا كاهش مصرف % | W7: درصد افزايش/كاهش | Y7: رخ داد ها
N8: زمان توليد | O8: تعداد توليد | W8: زمان توليد | X8: تعداد توليد
A9: 1 | B9: برق | D9: 1141200 | F9: 78.719735 | G9: 14796799200 | H9: 1304200 | J9: 267.41849 | L9: -12.498083 | N9: =Q78 -> 0.64285714 | O9: =R78 -> -0.15778772 | U9: 110.47506 | W9: =Q76 -> 2.2857143 | X9: =R76 -> 1.9725241
A10: 2 | B10: پساب صنعتی | D10: 22 | F10: 0.025028441 | G10: 26355626 | H10: 33 | J10: 0.037542662 | L10: -33.333333 | U10: 69.230769
B11: آب صنعتی | D11: 2.4146225e-05 | F11: 1.6656015e-09 | G11: 0 | H11: 0 | J11: 0 | L11: 0 | U11: 0
B12: آب نرم | D12: 609 | F12: 0.042008691 | G12: 729571647 | H12: 556 | J12: 0.11400451 | L12: 9.5323741 | U12: 55.357143
B13: آب شرب | D13: 1946 | F13: 0.13423467 | G13: 1406023920 | H13: 3133 | J13: 0.64240312 | L13: -37.887009 | U13: 56.054531
B14: آب Di | D14: 51 | F14: 0.0035179692 | G14: 92413.683 | H14: 0 | J14: 0 | L14: #DIV/0! | U14: 0
A15: 3 | B15: گازM3 | D15: 395570.86 | F15: 27.286395 | G15: 1.2870358e+10 | H15: 392965.53 | J15: 80.575257 | L15: 0.66299301 | P15: هنوز فاقد كنتور و ارقام مقايسه اي قبلي لحاظ مي شود. | U15: -26.133983
A16: 4 | B16: هوای فشرده | D16: 969850 | F16: 66.900048 | G16: 2054142300 | H16: 1382167.5 | J16: 283.40527 | L16: -29.831225 | U16: 117.79724
A17: جمع کل هزينه به ريال | G17: 3.1883343e+10
A18: وضعیت پروژه ها سال1405
A19: رديف | B19: كد شناسايي سيستم داخلي | D19: عنوان پروژه | I19: نوع حامل | J19: مقدار صرفه جوئی مصرف حامل | L19: واحد | M19: کاهش هزینه (ریال) | O19: تاریخ شروع اجراء پروژه | Q19: تاریخ پايان اجراء پروژه | S19: درصد اجراء پروژه | T19: شماره نامه | U19: کد ثبت مدیریت رنگ CPHR | X19: وضعيت انجام | Y19: توضيحات
A20: 1 | B20: P1E1-1402 | D20: پروژه ي بهينه سازي انرژي عايق بندي لوله هاي آب گرم و سرد ( سرمايش گرمايش فن كوييل ها ) سالن كنفرانس دنا | I20: برق | J20: 1200 | L20: KWH | M20: 1500000 | S20: 100 | T20: 14021913951 | U20: 12119 | X20: انجام شد
B21: P1F1-1402 | I21: آب | J21: - | L21: m^3
B22: - | I22: گاز | J22: 100 | L22: m^3 | M22: 10000000
B23: - | I23: هواي فشرده | J23: - | L23: m^3 | M23: -
A24: 2 | B24: P1E1-1402 | D24: پروژه ي بهينه سازي انرژي عايق بندي لوله هاي آب گرم و سرد ( سرمايش گرمايش فن كوييل ها ) سالن كنفرانس دنا | I24: برق | J24: 1200 | L24: KWH | M24: 1500000 | S24: 100 | T24: 14021913951 | U24: 12119 | X24: انجام شد
B25: P1F1-1402 | I25: آب | J25: - | L25: m^3
B26: - | I26: گاز | J26: 100 | L26: m^3 | M26: 10000000
B27: - | I27: هواي فشرده | J27: - | L27: m^3 | M27: -
A28: 3 | B28: P1E1-1402 | D28: پروژه ي بهينه سازي انرژي عايق بندي لوله هاي آب گرم و سرد ( سرمايش گرمايش فن كوييل ها ) سالن كنفرانس دنا | I28: برق | J28: 1200 | L28: KWH | M28: 1500000 | S28: 100 | T28: 14021913951 | U28: 12119 | X28: انجام شد
B29: P1F1-1402 | I29: آب | J29: - | L29: m^3
B30: - | I30: گاز | J30: 100 | L30: m^3 | M30: 10000000
B31: - | I31: هواي فشرده | J31: - | L31: m^3 | M31: -
A32: 4 | B32: P1E1-1402 | D32: پروژه ي بهينه سازي انرژي عايق بندي لوله هاي آب گرم و سرد ( سرمايش گرمايش فن كوييل ها ) سالن كنفرانس دنا | I32: برق | J32: 1200 | L32: KWH | M32: 1500000 | S32: 100 | T32: 14021913951 | U32: 12119 | X32: انجام شد
B33: P1F1-1402 | I33: آب | J33: - | L33: m^3
B34: - | I34: گاز | J34: 100 | L34: m^3 | M34: 10000000
B35: - | I35: هواي فشرده | J35: - | L35: m^3 | M35: -
A36: 5 | B36: P1E1-1402 | D36: پروژه ي بهينه سازي انرژي عايق بندي لوله هاي آب گرم و سرد ( سرمايش گرمايش فن كوييل ها ) سالن كنفرانس دنا | I36: برق | J36: 1200 | L36: KWH | M36: 1500000 | S36: 100 | T36: 14021913951 | U36: 12119 | X36: انجام شد
B37: P1F1-1402 | I37: آب | J37: - | L37: m^3
B38: - | I38: گاز | J38: 100 | L38: m^3 | M38: 10000000
B39: - | I39: هواي فشرده | J39: - | L39: m^3 | M39: -
A40: وضعیت ممیزی های انرژی 1405
...

Sheet Audit
A1: بانك مميزي مميزي انرژي
A2: ردیف | B2: اطلاعات مغايرت ها | K2: اقدام اصلاحی | O2: رفع مغایرت | P2: در حال پیگیری | Q2: تكرار پيگيري | R2: آخرين تاريخ پيگري | S2: توضیحات
B3: مديريت | C3: اداره | D3: سالن | E3: تاريخ انجام مميزي | F3: نوع مميزي | G3: كد مميزي | H3: نوع مغايرت | I3: شماره نامه ارجاعي | J3: شرح عنوان مغايرت | K3: اکشن اجراء | L3: مهلت رفع (روز) | M3: تاريخ رفع مغايرت | N3: اقدام پیشگیرانه
A4: 1 | B4: نت سالن هاي رنگ | C4: نت رنگ 1و 3 | D4: رنگ3 | E4: 1404/02/03 | F4: دوره اي - داخلي | G4: PIA | H4: برق | I4: 140411852356 | J4: عكس شماره 1 استفاده از تجهيزات پرمصرف( لامپ لگني سوله اي) | K4: تامين لامپ و رفع مغايرت | L4: 60 | M4: 1404/04/03 | N4: برنامه تامين و پيش بيني ذخيره لازم | P4: * | Q4: 1 | R4: 1405/02/03 | S4: درجهت تامين چراغ هاي ال اي دي، درخواست خريد به صورت تجميعي توسط واحد بهينه سازي انرژي ارسال گرديده است وتا اين لحظه به دليل عدم تحويل قطعه در سالن رنگ 3 تعويض نشده است
A5: 2 | B5: نت سالن هاي رنگ | C5: نت رنگ 1و 3 | D5: رنگ3 | E5: 1404/06/03 | F5: نامحسوس - داخلي | G5: UIA | H5: برق | I5: 140411842364 | J5: عكس شماره 2 استفاده از تجهيزات پرمصرف( لامپ فلورسنت ) | K5: تعويض لامپ فلورسنت با لامپ ال اي دي | L5: 7 | M5: 1404/06/10 | O5: * | Q5: 0
A6: 3 | B6: نت سالن هاي رنگ | C6: نت رنگ 1و 3 | D6: رنگ3 | E6: 1404/06/04 | F6: نامحسوس - خدمات فني | G6: UATS | H6: آب | I6: 140411869854 | J6: عكس شماره 3 نشتي آب از شير هاي رستوران | K6: رفع نشتي با تعويض و تعمير مغزي شير | L6: 7 | M6: 1404/06/11 | N6: تاكيد بركنترل چك ليست هاي مميزي | O6: * | Q6: 0
A7: 4 | B7: نت سالن هاي رنگ | C7: نت رنگ 1و 3 | D7: پيش رنگ3 | E7: 1404/08/04 | F7: دوره اي - خدمات فني | G7: PATS | H7: برق | I7: 14026486026 | J7: عكس شماره 4 استفاده از روشنايي فلورسنت در راهروي اداري و لول 0.0 | K7: تامين لامپ | L7: 60 | M7: 1404/10/04 | N7: پس از تامين لامپ درخواستي طي مراحل درخواست،لامپهاي فلورسنت تعويض ميگردند. | P7: * | Q7: 3 | R7: 1405/04/03 | S7: طي مراحل درخواست شماره 6500026941 توسط واحد بهينه سازي انرژي قطعات به صورت مرحله ايي در حال تامين مي باشد.پس از هر مرحله تامين ،لامپهاي فلورسنت تعويض ميگردند و طي مراحل درخواست نيز عنوان شده است كه با توجه به عدم شفافيت نحوه تامين لامپ هاي درخواستي، در صورت ثبت مغايرت با منشاء روشنايي مسئوليت با واحد بهينه سازي انرژي مي باشد.
A8: 5 | B8: نت سالن هاي رنگ | C8: نت رنگ 1و 3 | D8: پيش رنگ4 | E8: 1405/02/05 | F8: دوره اي - خدمات فني | G8: PATS | H8: گاز | I8: 14051748602 | J8: عكس شماره 5،بالا بودن دماي محيط اداري | K8: مغايرت نمي باشد | L8: - | M8: - | N8: - | O8: * | S8: محيط اداري سالن پيشرنگ 3 ، ما بين كوره رنگ 3 و مخازن pt-ed مي باشد و محيط در حالت عادي نيز گرم مي باشد و فن كويل هاي دفاتر نيز خاموش مي باشد.لازم به ذكر است انتهاي خط نيز دفاتري وجود دارند كه داراي محيط سرد مي باشند و با اين دفاتر مشترك هستند.از اينرو با توجه به فصل سرما ، آيتم مذكور مغايرت نمي باشد.
A9: 6 | B9: نت سالن هاي رنگ | C9: نت رنگ 1و 3 | D9: رنگ 1 | E9: 1405/02/01 | F9: سيستمي-خدمات فني | G9: SATS | H9: سيستمي | I9: 14051663310 | J9: عدم تطبيق ديتا بيس SAP باداده هاي ميداني اندازه گيري شده | K9: اندازه گيري مقادير اكچوآل در سايت + اصلاح در جدول | L9: 90 | M9: 1405/05/01 | N9: پروسه ي اصلاح سيستم ها - ايزو 50001 | O9: *
A10: 7 | B10: نت سالن هاي رنگ | C10: نت رنگ 1و 3 | D10: رنگ 1 | E10: 1405/02/25 | F10: نامحسوس - خدمات فني | G10: UATS | H10: آب | I10: 14051668101 | J10: پوسیدگی شدید لوله های موتورخانه سالن رنگ1 | K10: داراي RFQ اقدام مي باشد | L10: 120 | M10: 1405/02/25 | N10: اسكوپ كلي ترميم تجهيزات قديمي | O10: *
A11: 8 | B11: نت سالن هاي رنگ | C11: نت رنگ 1و 3 | D11: رنگ 1 | E11: 1405/03/04 | F11: دوره اي - داخلي | G11: PIA | H11: گاز | I11: 14051228554 | J11: شکستگی شیشه کابین رویه سالن رنگ1 | K11: داراي Mocr اقدام مي باشد | L11: 120 | M11: 1405/03/04 | N11: - | O11: * | Q11: -
A12: 9 | B12: نت سالن هاي رنگ | C12: نت رنگ 1و 3 | D12: رنگ 1 | E12: 1405/03/04 | F12: دوره اي - داخلي | G12: PIA | H12: برق | I12: 14051228554 | J12: عدم نظافت شیشه های سالن | K12: ارجاع به واحد نظافت سالن | L12: 7 | M12: 1405/03/04 | N12: تاكيد بركنترل چك ليست هاي مميزي | P12: * | Q12: 1 | R12: 1405/05/03
A13: 10 | B13: نت سالن هاي رنگ | C13: نت رنگ 1و 3 | D13: رنگ 1 | E13: 1405/05/13 | F13: نامحسوس - داخلي | G13: UIA | H13: آب | I13: 14051757719 | J13: نشتی آب از یخ ساز رستوران رنگ1 | K13: در دستور كار براي بازديد و MOCRقرار گرفت . | L13: 40 | M13: 1405/05/13 | N13: اسكوپ كلي ترميم تجهيزات قديمي | P13: * | Q13: 1 | R13: 1405/05/03
A14: 11 | B14: نت سالن هاي رنگ | C14: نت رنگ 1و 3 | D14: رنگ 1 | E14: 1405/05/25 | F14: چك ليست مميزي هفتگي داخلي | G14: IAWC | H14: برق | I14: 14051767321 | J14: وجود مهتابي نيم سوخته ، كابين آستر جديد | K14: در دستور كار براي تعويض | L14: 7 | M14: 1405/06/14 | O14: *
A15: 12 | B15: نت سالن هاي رنگ | C15: نت رنگ 1و 3 | D15: رنگ 1 | E15: 1405/06/05 | F15: دوره اي - خدمات فني | G15: PATS | H15: هواي فشرده | I15: 14051748602 | J15: نرمال نبودن خروجي اگزاست 2 عدد ايرموتور دي اسلج كابين استر | K15: ارسال كاتالوگ براي بررسي كارشناسي موضوع محل اختلاف | L15: 5 | M15: 1405/06/10 | N15: موضوع مورد تاييد سالن رنگ 1نيست . | P15: *
A16: 13 | B16: نت سالن هاي رنگ | C16: نت رنگ 1و 3 | D16: رنگ 1 | E16: 1405/06/05 | F16: دوره اي - خدمات فني | G16: PATS | H16: برق | I16: 14051748602 | J16: وجود 6 عدد پنل LED با توان 72 وات (پنل مربعي) | K16: شش عدد پنل هاي اضافي جمع اوري گرديد | L16: 10 | M16: 1405/06/15 | N16: بررسي موارد مشابه با لوكس غير مورد نياز | O16: *
A17: 14 | B17: نت سالن هاي رنگ | C17: نت رنگ 1و 3 | D17: رنگ 1 | E17: 1405/06/05 | F17: دوره اي - خدمات فني | G17: PATS | H17: هواي فشرده | I17: 14051748602 | J17: نشتي هواي فشرده از تابلو هندگان سمز در ضلع شمالي خط استر | K17: موضوع مرتفع گرديد . | L17: 15 | M17: 1405/06/20 | N17: تاكيد بر انجان چك ليست هاي هفتگي | O17: *
A18: 15 | B18: نت سالن هاي رنگ | C18: نت رنگ 1و 3 | D18: رنگ 1 | E18: 1405/06/05 | F18: دوره اي - خدمات فني | G18: PATS | H18: آب | I18: 14051748602 | J18: ريزش شديد آب از سيل پمپ هاي چيلر | K18: احتراما مغايرت فوق با فعاليت اچاركشي عينكي پمپ | L18: 5 | M18: 1405/06/10 | N18: تاكيد بر انجام چك ليست هاي هفتگي | O18: *

Sheet Projects
A1: ليست پروژه هاي انرژي سالن هاي رنگ 1 شركت ايرانخودرو
A2: رديف | B2: كد شناسايي سيستم داخلي | C2: عنوان پروژه | D2: مديريت | E2: اداره | F2: سالن | G2: سال ارائه | H2: حامل | I2: واحد حامل | J2: مقدار صرفه جوئی مصرف | K2: مقدار ریالی کاهش هزینه(ریال) | L2: هزينه اجرا | M2: کد ثبت مدیریت رنگ(کاهش هزینه) CPHR | N2: نامه ي پروژه | O2: نامه ي مرتبط | P2: شماره ي پيشنهاد | Q2: درصد اجراء | R2: پايلوت اجراء | S2: كد پرسنلي | T2: تاریخ شروع | U2: تاريخ خاتمه | V2: وضعيت | W2: توضيحات
A3: 1 | B3: P1E1-1402 | C3: پروژه ي بهينه سازي انرژي عايق بندي لوله هاي آب گرم و سرد ( سرمايش گرمايش فن كوييل ها ) سالن كنفرانس دنا | D3: نت سالن هاي رنگ | E3: نت رنگ 1و 3 | F3: رنگ1 | G3: 1402 | H3: برق | I3: KWH | J3: 190 | K3: 1500000 | L3: 20000000 | M3: 12119 | N3: 14021913951 | O3: - | P3: 1807212 | Q3: 1 | R3: صبوري | T3: 1401/10/15 | U3: 1402.02.30 | V3: انجام شد | W3: تهيه عايق و اجرا
B4: P1F1-1402 | H4: آب | I4: m^3 | J4: - | K4: -
B5: - | H5: گاز | I5: m^3 | J5: 100 | K5: 10000000
B6: - | H6: هواي فشرده | I6: m^3 | K6: -
A7: 2 | B7: P1E2-1402 | C7: اينتر لاك كردن كاركركرد كولر هاي گازي تابلو برق هاي كنترل هواساز هاي حوزه ي پروسس با زمان كاركرد الكرتو فن هاي آن | D7: نت سالن هاي رنگ | E7: نت رنگ 1و 3 | F7: رنگ1 | G7: 1402 | H7: برق | I7: KWH | J7: 28000 | K7: =J7*3080 -> 86240000 | L7: 0 | M7: 11967 | N7: 14021485237 | O7: - | P7: 1705108 | Q7: 1 | R7: حسن آبادي | T7: 1401.11.15 | U7: 1402.03.30 | V7: انجام شده
H8: آب | I8: m^3 | J8: 0 | K8: 0 | L8: 0
H9: گاز | I9: m^3 | J9: 0 | K9: 0 | L9: 0
H10: هواي فشرده | I10: m^3 | J10: 0 | K10: 0 | L10: 0
A11: 3 | B11: - | C11: پروژه بهينه سازي مصرف آب بازگرداني نشتي آب پمپ هاي سيركوله بويلرهاي سالن رنگ 1 به مدار اصلي جهت مصرف دوباره | D11: نت سالن هاي رنگ | E11: نت رنگ 1و 3 | F11: رنگ1 | G11: 1402 | H11: برق | I11: KWH | L11: 0 | M11: 11961 | N11: 14021456468 | O11: 140111534815 14021527874 14021576811 1402629117 14021793043 14021787305 14021787343 14021793043 1402638924 | P11: 1789569 | Q11: 0.15 | R11: روستايي | S11: 79210363 | T11: 1401/11/10 | U11: 1402/07/31 | V11: رها شده | W11: 1) قطعات از شامل 2) تابلو كنترل 3) سوراخ كردن سقف
B12: P1W3-1402 | H12: آب | I12: m^3 | J12: 200 | K12: =J12*449885 -> 89977000
H13: گاز | I13: m^3
H14: هواي فشرده | I14: m^3
A15: 4 | B15: - | C15: كاهش مصرف انرژي برق با اجراي كنترل اتوماتيك و برنامه ريزي شده ي هواكش هاي آكسيال تهويه سقفي محدود هي كوره شمال غربي سالن رنگ 1 | D15: نت سالن هاي رنگ | E15: نت رنگ 1و 3 | F15: رنگ1 | G15: 1405 | H15: برق | I15: KWH | J15: =K15/600 -> 66666.667 | K15: 40000000 | L15: 0 | M15: در حال تنظيم منشور پروژه | N15: در حال تنظيم منشور پروژه | O15: 1405141014 | P15: در حال تنظيم منشور پروژه | Q15: 0.15 | R15: روستايي | S15: 79210363 | T15: 1404/12/29 | U15: 1405/12/29 | V15: در جريان | W15: تهيه لگو ويا فرمان از كارت PLC بررسي شود
B16: P1W3-1405 | H16: آب | I16: m^3
B17: - | H17: گاز | I17: m^3
B18: - | H18: هواي فشرده | I18: m^3
A19: 5 | B19: - | C19: كاهش مصرف انرژي برق با اجراي كنترل اتوماتيك و برنامه ريزي شده ي هواكش هاي آكسيال تهويه سقفي محدوده ي پلتفرم PBS سالن رنگ 1 | D19: نت سالن هاي رنگ | E19: نت رنگ 1و 3 | F19: رنگ1 | G19: 1405 | H19: برق | I19: KWH | J19: =K19/600 -> 50000 | K19: 30000000 | L19: 0 | M19: در حال تنظيم منشور پروژه | N19: در حال تنظيم منشور پروژه | O19: 1405141014 | P19: در حال تنظيم منشور پروژه | Q19: 0.15 | R19: روستايي | S19: 79210363 | T19: 1401/11/10 | U19: 1405/12/29 | V19: در جريان | W19: تهيه لگو ويا فرمان از كارت PLC بررسي شود
B20: P1W3-1405 | H20: آب | I20: m^3
B21: - | H21: گاز | I21: m^3
B22: - | H22: هواي فشرده | I22: m^3
A23: 6 | B23: - | C23: كاهش مصرف سوخت با اصلاح Expantion Joint ايرسيل كوره ي 3 رويه | D23: نت سالن هاي رنگ | E23: نت رنگ 1و 3 | F23: رنگ1 | G23: 1405 | H23: برق | I23: KWH | L23: 0 | M23: در حال تنظيم منشور پروژه | N23: در حال تنظيم منشور پروژه | O23: 1405141014 | P23: در حال تنظيم منشور پروژه | Q23: 0.15 | R23: روستايي | S23: 79210363 | T23: 1401/11/10 | U23: 1405/12/29 | V23: در جريان | W23: تهيه لگو ويا فرمان از كارت PLC بررسي شود
B24: P1W3-1405 | H24: آب | I24: m^3
B25: - | H25: گاز | I25: m^3 | J25: 1500 | K25: 15000000
B26: - | H26: هواي فشرده | I26: m^3

Sheet Candle estick Chart
A1: توان مصرفي روزانه ( KW)
A2: روز ماه | B2: Open | C2: High | D2: Low | E2: Closed | F2: حد بالا KW | G2: حد پایین KW
A3: 1 | B3: =D3 -> 1850 | C3: 2099 | D3: 1850 | E3: 2099 | F3: ='Mountlly-R'!C52 -> 1904 | G3: ='Mountlly-R'!D52 -> 1440
A4: 2 | B4: 1811 | C4: 2100 | D4: 1811 | E4: 2100 | F4: =F3 -> 1904 | G4: =G3 -> 1440
A5: 4 | B5: 1831 | C5: 2110 | D5: 1831 | E5: 2110 | F5: =F4 -> 1904 | G5: =G4 -> 1440
A6: 5 | B6: 1803 | C6: 2103 | D6: 1803 | E6: 2103 | F6: =F5 -> 1904 | G6: =G5 -> 1440
A7: 6 | B7: 1836 | C7: 2022 | D7: 1836 | E7: 2022 | F7: =F6 -> 1904 | G7: =G6 -> 1440
A8: 7 | B8: 1821 | C8: 2078 | D8: 1821 | E8: 2078 | F8: =F7 -> 1904 | G8: =G7 -> 1440
A9: 8 | B9: 1833 | C9: 2086 | D9: 1833 | E9: 2086 | F9: =F8 -> 1904 | G9: =G8 -> 1440
A10: 9 | B10: 1834 | C10: 2053 | D10: 1834 | E10: 2053 | F10: =F9 -> 1904 | G10: =G9 -> 1440
A11: 10 | B11: 1835 | C11: 2100 | D11: 1835 | E11: 2100 | F11: =F10 -> 1904 | G11: =G10 -> 1440
A12: 11 | B12: 1850 | C12: 2079.9963 | D12: 1850 | E12: 2079.9963 | F12: =F11 -> 1904 | G12: =G11 -> 1440
A13: 12 | B13: 1860 | C13: 2060.1133 | D13: 1860 | E13: 2060.1133 | F13: =F12 -> 1904 | G13: =G12 -> 1440
A14: 13 | B14: 1809 | C14: 2044 | D14: 1809 | E14: 2044 | F14: =F13 -> 1904 | G14: =G13 -> 1440
A15: 14 | B15: 1815 | C15: 2024.352 | D15: 1815 | E15: 2024.352 | F15: =F14 -> 1904 | G15: =G14 -> 1440
... A32: 31 | B32: 1816 | C32: 2051 | D32: 1816 | E32: 2051 | F32: =F31 -> 1904 | G32: =G31 -> 1440
A34: Ave. | B34: =AVERAGE(B3:B32) -> 1832.5667 | C34: =AVERAGE(C3:C32) -> 2069.7602 | D34: =AVERAGE(D3:D32) -> 1832.5667 | E34: =AVERAGE(E3:E32) -> 2069.7602 | F34: =AVERAGE(F3:F32) -> 1904 | G34: =AVERAGE(G3:G32) -> 1440
A35: MinW1 | B35: =MIN(B3:B8) -> 1803
A36: MaxW1 | C36: =MAX(C3:C8) -> 2110
A37: MinW2 | B37: =MIN(B9:B15) -> 1809
A38: MaxW2 | C38: =MAX(C9:C15) -> 2100
A39: MinW3 | B39: =MIN(B16:B22) -> 1813
A40: MaxW3 | C40: =MAX(C16:C22) -> 2105
A41: MinW4 | B41: =MIN(B23:B29) -> 1806
A42: MaxW4 | C42: =MAX(C23:C29) -> 2097
A43: MinW5 | B43: =MIN(B30:B32) -> 1816
A44: MaxW5 | C44: =MAX( C30:C32) -> 2099

Sheet General- Info

Sheet Item Banks
A1: موارد ارجاع شده وبند هاي صورت جلسه هاي پيشين و آخرین وضعیت پيگيري
A2: ردیف | B2: اطلاعات جلسات و ارجاعات | S2: وضعیت پيگيريها | Z2: توضيحات
B3: سطح جلسه | D3: شماره نامه ارجاعي | F3: شماره نامه مرتبط | G3: حامل | H3: تاریخ ارجاع | I3: موارد ارجاع شده وبند هاي صورت جلسه ها | S3: تاريخ مهلت رفع مغايرت | U3: آخرين تاريخ پيگري | V3: رفع شده | W3: در حال پیگیری | Y3: تعداد تكرار | Z3: ملاحظات
A4: 1 | B4: پايلوت بخش | D4: 14051663235 | G4: كليه حامل ها | H4: 1405/02/01 | I4: در راستاي اجراي صحيح ايتم 2 مقرر شد جلسه توجيهي توسط نمايندگان انرژي با سر گروه هاي بخش ها برگزار شود | S4: 1405/04/11 | U4: 1405/05/11 | V4: * | Y4: 2 | Z4: باهماهنگي واحد هواي فشرده در روز تعطيل
A5: 2 | B5: پايلوت نت پشتياني | D5: 14051621101 | G5: آب | H5: 1405/02/25 | I5: تكميل و ارسال فرم بانك اطلاعات آب (به دليل عدم انجام تاريخ مجدد ثبت شد) | S5: 1405/03/05 | U5: 1405/04/11 | W5: * | Y5: 1
A6: 3 | B6: اداره نت | D6: 14051228333 | G6: كليه حامل ها | H6: 1405/01/24 | I6: ارسال فرم منشور پروژه هاي بهبود سال 1405 | S6: 1405/02/16 | U6: 1405/03/04 | V6: * | Y6: 0 | Z6: فرمت هاي جديد 1405 دريافت شود .
A7: 4 | B7: مشترك نت با بهينه سازي | D7: 14051228119 | G7: سيستمي | H7: 1405/01/26 | I7: اصلاح اطلاعات تجهيزات در sap در راستاي مميزي هاي iso 50001 (ثبت اولويت هاي تعين شده تا پايان خرداد ماه) | S7: 1405/02/10 | U7: 1405/06/04 | V7: * | Y7: 1
A8: 5 | B8: ارجاعات اداره بهينه سازي انرژي | D8: 14051428126 | G8: هواي فشره | H8: 1405/01/28 | I8: اجراي سناريوي باز و بسته كردن شيرهاي هواي فشرده سالن هاي رنگ و رنگ3 و رنگ1 | S8: 1405/02/29 | U8: 1405/04/05 | W8: * | Y8: 2
A9: 6 | B9: ارجاعات اداره بهينه سازي انرژي | D9: 14051127710 | G9: آب | H9: 1405/02/13 | I9: نشتی آب از یخ ساز رستوران رنگ1 | S9: 1405/03/02 | U9: 1405/04/06 | W9: * | Y9: 3 | Z9: Mocr85369
